Workbook

Sheet القائمة الإسمية للمترشحين
A1: الجمهورية الجزائرية الديموقراطية الشعبية
A2: وزارة التعليم العالي والبحث العلمي
A3: جامعة عمــــــــــار ثليـجي - الأغــــــــــــــــــــــــــــــــــــواط
A4: كلية : العلوم الاقتصادية و التجارية و علوم التسيير
B6: محضر ترميز المترشحين لـمسابقة التكوين في الطور الثالث دكتوراه
A7: المرجع: القرار رقم 547 المؤرخ في 02-06-2016 ( وزارة التعليم العالي و البحث العلمي)
B8: التخصص : إدارة المؤسسات
B10: القائمة الإسمية للمترشحين للمسابقة
B14: اللقب | C14: الإسم | D14: تالايخ الازدياد | E14: الجامعة الأصلية | F14: الرمز السري للمترشح | G14: ملاحظة
A15: 1 | B15: الطالب 1 | C15: الطالب 1 | D15: تالايخ الازدياد | F15: G201
A16: 2 | B16: الطالب 2 | C16: الطالب 2 | D16: تالايخ الازدياد | F16: G202 | L16: /
A17: 3 | B17: الطالب 3 | C17: الطالب 3 | D17: تالايخ الازدياد | F17: G203 | L17: غائب(ة)
L18: منقطع
F96: مسؤول مركز الامتحان

Sheet حجز النقاط المقياس الأول
A1: الجمهورية الجزائرية الديموقراطية الشعبية
A2: وزارة التعليم العالي والبحث العلمي
A3: جامعة عمــــــــــار ثليـجي - الأغــــــــــــــــــــــــــــــــــــواط
A4: كلية : العلوم الاقتصادية و التجارية و علوم التسيير
B6: محضر مداولات لمسابقة التكوين في الطور الثالث دكتوراه
A7: المرجع: القرار رقم 547 المؤرخ في 02-06-2016 ( وزارة التعليم العالي و البحث العلمي)
B8: التخصص : إدارة المؤسسات
A10: النتائج النهائية التصحيح الأول
B12: الرمز السري للمترشح | C12: إدخال علامات المسابقة
C13: الامتحـــــــان الأول :إدارة الموارد البشرية
A14: الرقم | B14: الرمز السري | C14: التصحيح الأول | D14: التصحيح الثاني | E14: حالات التصحيح الثالث | F14: التصحيح الثالث | G14: لا يوجد تصحيح ثالث | H14: 3 1 | I14: 3 2 | J14: 1 2 | K14: وجود تصحيح ثالث | L14: علامة الإمتحان 1 | P14: Min | Q14: 1 3 | R14: 2 3 | S14: 1 2
A15: 1 | B15: ='القائمة الإسمية للمترشحين'!F15 -> G201 | C15: 0 | D15: 0 | E15: =IF(ABS(C15-D15)>=3,"يتطلب التصحيح الثالث"," ") | F15: 0 | G15: =IF(E15=" ",(C15+D15)/2," ") -> 0 | H15: =ABS(C15-F15) -> 0 | I15: =ABS(D15-F15) -> 0 | J15: =ABS(C15-D15) -> 0 | K15: =IF(E15=" "," ",IF(H15<I15,(F15+C15)/2,(F15+D15)/2)) | L15: =MAX(Q15:S15) -> 0 | P15: =MIN(H15:J15) -> 0 | Q15: =IF(P15=H15,(F15+C15)/2,0) -> 0 | R15: =IF(P15=I15,(F15+D15)/2,0) -> 0 | S15: =IF(P15=J15,(D15+C15)/2,0) -> 0
A16: 2 | B16: ='القائمة الإسمية للمترشحين'!F16 -> G202 | C16: 0 | D16: 0 | E16: =IF(ABS(C16-D16)>=3,"يتطلب التصحيح الثالث"," ") | F16: 0 | G16: =IF(E16=" ",(C16+D16)/2," ") -> 0 | H16: =ABS(C16-F16) -> 0 | I16: =ABS(D16-F16) -> 0 | J16: =ABS(C16-D16) -> 0 | K16: =IF(E16=" "," ",IF(H16<I16,(F16+C16)/2,(F16+D16)/2)) | L16: =MAX(Q16:S16) -> 0 | M16: إمضاء لجنة التصحيح | P16: =MIN(H16:J16) -> 0 | Q16: =IF(P16=H16,(F16+C16)/2,0) -> 0 | R16: =IF(P16=I16,(F16+D16)/2,0) -> 0 | S16: =IF(P16=J16,(D16+C16)/2,0) -> 0
A17: 3 | B17: ='القائمة الإسمية للمترشحين'!F17 -> G203 | C17: 0 | D17: 0 | E17: =IF(ABS(C17-D17)>=3,"يتطلب التصحيح الثالث"," ") | F17: 0 | G17: =IF(E17=" ",(C17+D17)/2," ") -> 0 | H17: =ABS(C17-F17) -> 0 | I17: =ABS(D17-F17) -> 0 | J17: =ABS(C17-D17) -> 0 | K17: =IF(E17=" "," ",IF(H17<I17,(F17+C17)/2,(F17+D17)/2)) | L17: =MAX(Q17:S17) -> 0 | P17: =MIN(H17:J17) -> 0 | Q17: =IF(P17=H17,(F17+C17)/2,0) -> 0 | R17: =IF(P17=I17,(F17+D17)/2,0) -> 0 | S17: =IF(P17=J17,(D17+C17)/2,0) -> 0
A18: 4 | B18: ='القائمة الإسمية للمترشحين'!F18 -> 0 | C18: 0 | D18: 0 | E18: =IF(ABS(C18-D18)>=3,"يتطلب التصحيح الثالث"," ") | F18: 0 | G18: =IF(E18=" ",(C18+D18)/2," ") -> 0 | H18: =ABS(C18-F18) -> 0 | I18: =ABS(D18-F18) -> 0 | J18: =ABS(C18-D18) -> 0 | K18: =IF(E18=" "," ",IF(H18<I18,(F18+C18)/2,(F18+D18)/2)) | L18: =MAX(Q18:S18) -> 0 | P18: =MIN(H18:J18) -> 0 | Q18: =IF(P18=H18,(F18+C18)/2,0) -> 0 | R18: =IF(P18=I18,(F18+D18)/2,0) -> 0 | S18: =IF(P18=J18,(D18+C18)/2,0) -> 0
A19: 5 | B19: ='القائمة الإسمية للمترشحين'!F19 -> 0 | C19: 0 | D19: 0 | E19: =IF(ABS(C19-D19)>=3,"يتطلب التصحيح الثالث"," ") | F19: 0 | G19: =IF(E19=" ",(C19+D19)/2," ") -> 0 | H19: =ABS(C19-F19) -> 0 | I19: =ABS(D19-F19) -> 0 | J19: =ABS(C19-D19) -> 0 | K19: =IF(E19=" "," ",IF(H19<I19,(F19+C19)/2,(F19+D19)/2)) | L19: =MAX(Q19:S19) -> 0 | P19: =MIN(H19:J19) -> 0 | Q19: =IF(P19=H19,(F19+C19)/2,0) -> 0 | R19: =IF(P19=I19,(F19+D19)/2,0) -> 0 | S19: =IF(P19=J19,(D19+C19)/2,0) -> 0
A20: 6 | B20: ='القائمة الإسمية للمترشحين'!F20 -> 0 | C20: 0 | D20: 0 | E20: =IF(ABS(C20-D20)>=3,"يتطلب التصحيح الثالث"," ") | F20: 0 | G20: =IF(E20=" ",(C20+D20)/2," ") -> 0 | H20: =ABS(C20-F20) -> 0 | I20: =ABS(D20-F20) -> 0 | J20: =ABS(C20-D20) -> 0 | K20: =IF(E20=" "," ",IF(H20<I20,(F20+C20)/2,(F20+D20)/2)) | L20: =MAX(Q20:S20) -> 0 | P20: =MIN(H20:J20) -> 0 | Q20: =IF(P20=H20,(F20+C20)/2,0) -> 0 | R20: =IF(P20=I20,(F20+D20)/2,0) -> 0 | S20: =IF(P20=J20,(D20+C20)/2,0) -> 0
A21: 7 | B21: ='القائمة الإسمية للمترشحين'!F21 -> 0 | C21: 0 | D21: 0 | E21: =IF(ABS(C21-D21)>=3,"يتطلب التصحيح الثالث"," ") | F21: 0 | G21: =IF(E21=" ",(C21+D21)/2," ") -> 0 | H21: =ABS(C21-F21) -> 0 | I21: =ABS(D21-F21) -> 0 | J21: =ABS(C21-D21) -> 0 | K21: =IF(E21=" "," ",IF(H21<I21,(F21+C21)/2,(F21+D21)/2)) | L21: =MAX(Q21:S21) -> 0 | P21: =MIN(H21:J21) -> 0 | Q21: =IF(P21=H21,(F21+C21)/2,0) -> 0 | R21: =IF(P21=I21,(F21+D21)/2,0) -> 0 | S21: =IF(P21=J21,(D21+C21)/2,0) -> 0
A22: 8 | B22: ='القائمة الإسمية للمترشحين'!F22 -> 0 | C22: 0 | D22: 0 | E22: =IF(ABS(C22-D22)>=3,"يتطلب التصحيح الثالث"," ") | F22: 0 | G22: =IF(E22=" ",(C22+D22)/2," ") -> 0 | H22: =ABS(C22-F22) -> 0 | I22: =ABS(D22-F22) -> 0 | J22: =ABS(C22-D22) -> 0 | K22: =IF(E22=" "," ",IF(H22<I22,(F22+C22)/2,(F22+D22)/2)) | L22: =MAX(Q22:S22) -> 0 | P22: =MIN(H22:J22) -> 0 | Q22: =IF(P22=H22,(F22+C22)/2,0) -> 0 | R22: =IF(P22=I22,(F22+D22)/2,0) -> 0 | S22: =IF(P22=J22,(D22+C22)/2,0) -> 0
A23: 9 | B23: ='القائمة الإسمية للمترشحين'!F23 -> 0 | C23: 0 | D23: 0 | E23: =IF(ABS(C23-D23)>=3,"يتطلب التصحيح الثالث"," ") | F23: 0 | G23: =IF(E23=" ",(C23+D23)/2," ") -> 0 | H23: =ABS(C23-F23) -> 0 | I23: =ABS(D23-F23) -> 0 | J23: =ABS(C23-D23) -> 0 | K23: =IF(E23=" "," ",IF(H23<I23,(F23+C23)/2,(F23+D23)/2)) | L23: =MAX(Q23:S23) -> 0 | P23: =MIN(H23:J23) -> 0 | Q23: =IF(P23=H23,(F23+C23)/2,0) -> 0 | R23: =IF(P23=I23,(F23+D23)/2,0) -> 0 | S23: =IF(P23=J23,(D23+C23)/2,0) -> 0
A24: 10 | B24: ='القائمة الإسمية للمترشحين'!F24 -> 0 | C24: 0 | D24: 0 | E24: =IF(ABS(C24-D24)>=3,"يتطلب التصحيح الثالث"," ") | F24: 0 | G24: =IF(E24=" ",(C24+D24)/2," ") -> 0 | H24: =ABS(C24-F24) -> 0 | I24: =ABS(D24-F24) -> 0 | J24: =ABS(C24-D24) -> 0 | K24: =IF(E24=" "," ",IF(H24<I24,(F24+C24)/2,(F24+D24)/2)) | L24: =MAX(Q24:S24) -> 0 | P24: =MIN(H24:J24) -> 0 | Q24: =IF(P24=H24,(F24+C24)/2,0) -> 0 | R24: =IF(P24=I24,(F24+D24)/2,0) -> 0 | S24: =IF(P24=J24,(D24+C24)/2,0) -> 0
A25: 11 | B25: ='القائمة الإسمية للمترشحين'!F25 -> 0 | C25: 0 | D25: 0 | E25: =IF(ABS(C25-D25)>=3,"يتطلب التصحيح الثالث"," ") | F25: 0 | G25: =IF(E25=" ",(C25+D25)/2," ") -> 0 | H25: =ABS(C25-F25) -> 0 | I25: =ABS(D25-F25) -> 0 | J25: =ABS(C25-D25) -> 0 | K25: =IF(E25=" "," ",IF(H25<I25,(F25+C25)/2,(F25+D25)/2)) | L25: =MAX(Q25:S25) -> 0 | P25: =MIN(H25:J25) -> 0 | Q25: =IF(P25=H25,(F25+C25)/2,0) -> 0 | R25: =IF(P25=I25,(F25+D25)/2,0) -> 0 | S25: =IF(P25=J25,(D25+C25)/2,0) -> 0
A26: 12 | B26: ='القائمة الإسمية للمترشحين'!F26 -> 0 | C26: 0 | D26: 0 | E26: =IF(ABS(C26-D26)>=3,"يتطلب التصحيح الثالث"," ") | F26: 0 | G26: =IF(E26=" ",(C26+D26)/2," ") -> 0 | H26: =ABS(C26-F26) -> 0 | I26: =ABS(D26-F26) -> 0 | J26: =ABS(C26-D26) -> 0 | K26: =IF(E26=" "," ",IF(H26<I26,(F26+C26)/2,(F26+D26)/2)) | L26: =MAX(Q26:S26) -> 0 | P26: =MIN(H26:J26) -> 0 | Q26: =IF(P26=H26,(F26+C26)/2,0) -> 0 | R26: =IF(P26=I26,(F26+D26)/2,0) -> 0 | S26: =IF(P26=J26,(D26+C26)/2,0) -> 0
A27: 13 | B27: ='القائمة الإسمية للمترشحين'!F27 -> 0 | C27: 0 | D27: 0 | E27: =IF(ABS(C27-D27)>=3,"يتطلب التصحيح الثالث"," ") | F27: 0 | G27: =IF(E27=" ",(C27+D27)/2," ") -> 0 | H27: =ABS(C27-F27) -> 0 | I27: =ABS(D27-F27) -> 0 | J27: =ABS(C27-D27) -> 0 | K27: =IF(E27=" "," ",IF(H27<I27,(F27+C27)/2,(F27+D27)/2)) | L27: =MAX(Q27:S27) -> 0 | P27: =MIN(H27:J27) -> 0 | Q27: =IF(P27=H27,(F27+C27)/2,0) -> 0 | R27: =IF(P27=I27,(F27+D27)/2,0) -> 0 | S27: =IF(P27=J27,(D27+C27)/2,0) -> 0
A28: 14 | B28: ='القائمة الإسمية للمترشحين'!F28 -> 0 | C28: 0 | D28: 0 | E28: =IF(ABS(C28-D28)>=3,"يتطلب التصحيح الثالث"," ") | F28: 0 | G28: =IF(E28=" ",(C28+D28)/2," ") -> 0 | H28: =ABS(C28-F28) -> 0 | I28: =ABS(D28-F28) -> 0 | J28: =ABS(C28-D28) -> 0 | K28: =IF(E28=" "," ",IF(H28<I28,(F28+C28)/2,(F28+D28)/2)) | L28: =MAX(Q28:S28) -> 0 | P28: =MIN(H28:J28) -> 0 | Q28: =IF(P28=H28,(F28+C28)/2,0) -> 0 | R28: =IF(P28=I28,(F28+D28)/2,0) -> 0 | S28: =IF(P28=J28,(D28+C28)/2,0) -> 0
... A62: 48 | B62: ='القائمة الإسمية للمترشحين'!F62 -> 0 | C62: 0 | D62: 0 | E62: =IF(ABS(C62-D62)>=3,"يتطلب التصحيح الثالث"," ") | F62: 0 | G62: =IF(E62=" ",(C62+D62)/2," ") -> 0 | H62: =ABS(C62-F62) -> 0 | I62: =ABS(D62-F62) -> 0 | J62: =ABS(C62-D62) -> 0 | K62: =IF(E62=" "," ",IF(H62<I62,(F62+C62)/2,(F62+D62)/2)) | L62: =MAX(Q62:S62) -> 0 | P62: =MIN(H62:J62) -> 0 | Q62: =IF(P62=H62,(F62+C62)/2,0) -> 0 | R62: =IF(P62=I62,(F62+D62)/2,0) -> 0 | S62: =IF(P62=J62,(D62+C62)/2,0) -> 0
A63: 49 | B63: ='القائمة الإسمية للمترشحين'!F63 -> 0 | C63: 0 | D63: 0 | E63: =IF(ABS(C63-D63)>=3,"يتطلب التصحيح الثالث"," ") | F63: 0 | G63: =IF(E63=" ",(C63+D63)/2," ") -> 0 | H63: =ABS(C63-F63) -> 0 | I63: =ABS(D63-F63) -> 0 | J63: =ABS(C63-D63) -> 0 | K63: =IF(E63=" "," ",IF(H63<I63,(F63+C63)/2,(F63+D63)/2)) | L63: =MAX(Q63:S63) -> 0 | M63: إمضاء لجنة التصحيح | P63: =MIN(H63:J63) -> 0 | Q63: =IF(P63=H63,(F63+C63)/2,0) -> 0 | R63: =IF(P63=I63,(F63+D63)/2,0) -> 0 | S63: =IF(P63=J63,(D63+C63)/2,0) -> 0
A64: 50 | B64: ='القائمة الإسمية للمترشحين'!F64 -> 0 | C64: 0 | D64: 0 | E64: =IF(ABS(C64-D64)>=3,"يتطلب التصحيح الثالث"," ") | F64: 0 | G64: =IF(E64=" ",(C64+D64)/2," ") -> 0 | H64: =ABS(C64-F64) -> 0 | I64: =ABS(D64-F64) -> 0 | J64: =ABS(C64-D64) -> 0 | K64: =IF(E64=" "," ",IF(H64<I64,(F64+C64)/2,(F64+D64)/2)) | L64: =MAX(Q64:S64) -> 0 | P64: =MIN(H64:J64) -> 0 | Q64: =IF(P64=H64,(F64+C64)/2,0) -> 0 | R64: =IF(P64=I64,(F64+D64)/2,0) -> 0 | S64: =IF(P64=J64,(D64+C64)/2,0) -> 0
A65: 51 | B65: ='القائمة الإسمية للمترشحين'!F65 -> 0 | C65: 0 | D65: 0 | E65: =IF(ABS(C65-D65)>=3,"يتطلب التصحيح الثالث"," ") | F65: 0 | G65: =IF(E65=" ",(C65+D65)/2," ") -> 0 | H65: =ABS(C65-F65) -> 0 | I65: =ABS(D65-F65) -> 0 | J65: =ABS(C65-D65) -> 0 | K65: =IF(E65=" "," ",IF(H65<I65,(F65+C65)/2,(F65+D65)/2)) | L65: =MAX(Q65:S65) -> 0 | P65: =MIN(H65:J65) -> 0 | Q65: =IF(P65=H65,(F65+C65)/2,0) -> 0 | R65: =IF(P65=I65,(F65+D65)/2,0) -> 0 | S65: =IF(P65=J65,(D65+C65)/2,0) -> 0
L68: إمضاء مسؤول أمانة المسابقة

Sheet حجز النقاط المقياس الثاني
A1: الجمهورية الجزائرية الديموقراطية الشعبية
A2: وزارة التعليم العالي والبحث العلمي
A3: جامعة عمــــــــــار ثليـجي - الأغــــــــــــــــــــــــــــــــــــواط
A4: كلية : العلوم الاقتصادية و التجارية و علوم التسيير
B6: محضر مداولات لمسابقة التكوين في الطور الثالث دكتوراه
A7: المرجع: القرار رقم 547 المؤرخ في 02-06-2016 ( وزارة التعليم العالي و البحث العلمي)
B8: التخصص : إدارة المؤسسات
B10: النتائج النهائية التصحيح الثاني
B12: الرمز السري للمترشح | D12: إدخال علامات المسابقة
D13: الامتحـــــــان الثاني :الإدارة الإسترتيجية
A14: الرقم | B14: الرمز السري | C14: التصحيح الأول | D14: التصحيح الثاني | E14: حالات التصحيح الثالث | F14: التصحيح الثالث | G14: لا يوجد تصحيح ثالث | H14: 3 1 | I14: 3 2 | J14: 1 2 | K14: وجود تصحيح ثالث | L14: علامة الإمتحان 1 | P14: Min | Q14: 3 1 | R14: 3 2 | S14: 1 2
A15: 1 | B15: ='القائمة الإسمية للمترشحين'!F15 -> G201 | C15: 0 | D15: 0 | E15: =IF(ABS(C15-D15)>=3,"يتطلب التصحيح الثالث"," ") | F15: 0 | G15: =IF(E15=" ",(C15+D15)/2," ") -> 0 | H15: =ABS(F15-C15) -> 0 | I15: =ABS(D15-F15) -> 0 | J15: =ABS(C15-D15) -> 0 | K15: =IF(E15=" "," ",IF(H15<I15,(F15+C15)/2,(F15+D15)/2)) | L15: =MAX(Q15:S15) -> 0 | P15: =MIN(H15:J15) -> 0 | Q15: =IF(P15=H15,(F15+C15)/2,0) -> 0 | R15: =IF(P15=I15,(F15+D15)/2,0) -> 0 | S15: =IF(P15=J15,(D15+C15)/2,0) -> 0
A16: 2 | B16: ='القائمة الإسمية للمترشحين'!F16 -> G202 | C16: 0 | D16: 0 | E16: =IF(ABS(C16-D16)>=3,"يتطلب التصحيح الثالث"," ") | F16: 0 | G16: =IF(E16=" ",(C16+D16)/2," ") -> 0 | H16: =ABS(F16-C16) -> 0 | I16: =ABS(D16-F16) -> 0 | J16: =ABS(C16-D16) -> 0 | K16: 0 | L16: =MAX(Q16:S16) -> 0 | M16: إمضاء لجنة التصحيح | P16: =MIN(H16:J16) -> 0 | Q16: =IF(P16=H16,(F16+C16)/2,0) -> 0 | R16: =IF(P16=I16,(F16+D16)/2,0) -> 0 | S16: =IF(P16=J16,(D16+C16)/2,0) -> 0
A17: 3 | B17: ='القائمة الإسمية للمترشحين'!F17 -> G203 | C17: 0 | D17: 0 | E17: =IF(ABS(C17-D17)>=3,"يتطلب التصحيح الثالث"," ") | F17: 0 | G17: =IF(E17=" ",(C17+D17)/2," ") -> 0 | H17: =ABS(F17-C17) -> 0 | I17: =ABS(D17-F17) -> 0 | J17: =ABS(C17-D17) -> 0 | K17: =IF(E17=" "," ",IF(H17<I17,(F17+C17)/2,(F17+D17)/2)) | L17: =MAX(Q17:S17) -> 0 | P17: =MIN(H17:J17) -> 0 | Q17: =IF(P17=H17,(F17+C17)/2,0) -> 0 | R17: =IF(P17=I17,(F17+D17)/2,0) -> 0 | S17: =IF(P17=J17,(D17+C17)/2,0) -> 0
A18: 4 | B18: ='القائمة الإسمية للمترشحين'!F18 -> 0 | C18: 0 | D18: 0 | E18: =IF(ABS(C18-D18)>=3,"يتطلب التصحيح الثالث"," ") | F18: 0 | G18: =IF(E18=" ",(C18+D18)/2," ") -> 0 | H18: =ABS(F18-C18) -> 0 | I18: =ABS(D18-F18) -> 0 | J18: =ABS(C18-D18) -> 0 | K18: 0 | L18: =MAX(Q18:S18) -> 0 | P18: =MIN(H18:J18) -> 0 | Q18: =IF(P18=H18,(F18+C18)/2,0) -> 0 | R18: =IF(P18=I18,(F18+D18)/2,0) -> 0 | S18: =IF(P18=J18,(D18+C18)/2,0) -> 0
A19: 5 | B19: ='القائمة الإسمية للمترشحين'!F19 -> 0 | C19: 0 | D19: 0 | E19: =IF(ABS(C19-D19)>=3,"يتطلب التصحيح الثالث"," ") | F19: 0 | G19: =IF(E19=" ",(C19+D19)/2," ") -> 0 | H19: =ABS(F19-C19) -> 0 | I19: =ABS(D19-F19) -> 0 | J19: =ABS(C19-D19) -> 0 | K19: 0 | L19: =MAX(Q19:S19) -> 0 | P19: =MIN(H19:J19) -> 0 | Q19: =IF(P19=H19,(F19+C19)/2,0) -> 0 | R19: =IF(P19=I19,(F19+D19)/2,0) -> 0 | S19: =IF(P19=J19,(D19+C19)/2,0) -> 0
A20: 6 | B20: ='القائمة الإسمية للمترشحين'!F20 -> 0 | C20: 0 | D20: 0 | E20: =IF(ABS(C20-D20)>=3,"يتطلب التصحيح الثالث"," ") | F20: 0 | G20: =IF(E20=" ",(C20+D20)/2," ") -> 0 | H20: =ABS(F20-C20) -> 0 | I20: =ABS(D20-F20) -> 0 | J20: =ABS(C20-D20) -> 0 | K20: 0 | L20: =MAX(Q20:S20) -> 0 | P20: =MIN(H20:J20) -> 0 | Q20: =IF(P20=H20,(F20+C20)/2,0) -> 0 | R20: =IF(P20=I20,(F20+D20)/2,0) -> 0 | S20: =IF(P20=J20,(D20+C20)/2,0) -> 0
A21: 7 | B21: ='القائمة الإسمية للمترشحين'!F21 -> 0 | C21: 0 | D21: 0 | E21: =IF(ABS(C21-D21)>=3,"يتطلب التصحيح الثالث"," ") | F21: 0 | G21: =IF(E21=" ",(C21+D21)/2," ") -> 0 | H21: =ABS(F21-C21) -> 0 | I21: =ABS(D21-F21) -> 0 | J21: =ABS(C21-D21) -> 0 | K21: 0 | L21: =MAX(Q21:S21) -> 0 | P21: =MIN(H21:J21) -> 0 | Q21: =IF(P21=H21,(F21+C21)/2,0) -> 0 | R21: =IF(P21=I21,(F21+D21)/2,0) -> 0 | S21: =IF(P21=J21,(D21+C21)/2,0) -> 0
A22: 8 | B22: ='القائمة الإسمية للمترشحين'!F22 -> 0 | C22: 0 | D22: 0 | E22: =IF(ABS(C22-D22)>=3,"يتطلب التصحيح الثالث"," ") | F22: 0 | G22: =IF(E22=" ",(C22+D22)/2," ") -> 0 | H22: =ABS(F22-C22) -> 0 | I22: =ABS(D22-F22) -> 0 | J22: =ABS(C22-D22) -> 0 | K22: 0 | L22: =MAX(Q22:S22) -> 0 | P22: =MIN(H22:J22) -> 0 | Q22: =IF(P22=H22,(F22+C22)/2,0) -> 0 | R22: =IF(P22=I22,(F22+D22)/2,0) -> 0 | S22: =IF(P22=J22,(D22+C22)/2,0) -> 0
A23: 9 | B23: ='القائمة الإسمية للمترشحين'!F23 -> 0 | C23: 0 | D23: 0 | E23: =IF(ABS(C23-D23)>=3,"يتطلب التصحيح الثالث"," ") | F23: 0 | G23: =IF(E23=" ",(C23+D23)/2," ") -> 0 | H23: =ABS(F23-C23) -> 0 | I23: =ABS(D23-F23) -> 0 | J23: =ABS(C23-D23) -> 0 | K23: 0 | L23: =MAX(Q23:S23) -> 0 | P23: =MIN(H23:J23) -> 0 | Q23: =IF(P23=H23,(F23+C23)/2,0) -> 0 | R23: =IF(P23=I23,(F23+D23)/2,0) -> 0 | S23: =IF(P23=J23,(D23+C23)/2,0) -> 0
A24: 10 | B24: ='القائمة الإسمية للمترشحين'!F24 -> 0 | C24: 0 | D24: 0 | E24: =IF(ABS(C24-D24)>=3,"يتطلب التصحيح الثالث"," ") | F24: 0 | G24: =IF(E24=" ",(C24+D24)/2," ") -> 0 | H24: =ABS(F24-C24) -> 0 | I24: =ABS(D24-F24) -> 0 | J24: =ABS(C24-D24) -> 0 | K24: 0 | L24: =MAX(Q24:S24) -> 0 | P24: =MIN(H24:J24) -> 0 | Q24: =IF(P24=H24,(F24+C24)/2,0) -> 0 | R24: =IF(P24=I24,(F24+D24)/2,0) -> 0 | S24: =IF(P24=J24,(D24+C24)/2,0) -> 0
A25: 11 | B25: ='القائمة الإسمية للمترشحين'!F25 -> 0 | C25: 0 | D25: 0 | E25: =IF(ABS(C25-D25)>=3,"يتطلب التصحيح الثالث"," ") | F25: 0 | G25: =IF(E25=" ",(C25+D25)/2," ") -> 0 | H25: =ABS(F25-C25) -> 0 | I25: =ABS(D25-F25) -> 0 | J25: =ABS(C25-D25) -> 0 | K25: 0 | L25: =MAX(Q25:S25) -> 0 | P25: =MIN(H25:J25) -> 0 | Q25: =IF(P25=H25,(F25+C25)/2,0) -> 0 | R25: =IF(P25=I25,(F25+D25)/2,0) -> 0 | S25: =IF(P25=J25,(D25+C25)/2,0) -> 0
A26: 12 | B26: ='القائمة الإسمية للمترشحين'!F26 -> 0 | C26: 0 | D26: 0 | E26: =IF(ABS(C26-D26)>=3,"يتطلب التصحيح الثالث"," ") | F26: 0 | G26: =IF(E26=" ",(C26+D26)/2," ") -> 0 | H26: =ABS(F26-C26) -> 0 | I26: =ABS(D26-F26) -> 0 | J26: =ABS(C26-D26) -> 0 | K26: 0 | L26: =MAX(Q26:S26) -> 0 | P26: =MIN(H26:J26) -> 0 | Q26: =IF(P26=H26,(F26+C26)/2,0) -> 0 | R26: =IF(P26=I26,(F26+D26)/2,0) -> 0 | S26: =IF(P26=J26,(D26+C26)/2,0) -> 0
A27: 13 | B27: ='القائمة الإسمية للمترشحين'!F27 -> 0 | C27: 0 | D27: 0 | E27: =IF(ABS(C27-D27)>=3,"يتطلب التصحيح الثالث"," ") | F27: 0 | G27: =IF(E27=" ",(C27+D27)/2," ") -> 0 | H27: =ABS(F27-C27) -> 0 | I27: =ABS(D27-F27) -> 0 | J27: =ABS(C27-D27) -> 0 | K27: 0 | L27: =MAX(Q27:S27) -> 0 | P27: =MIN(H27:J27) -> 0 | Q27: =IF(P27=H27,(F27+C27)/2,0) -> 0 | R27: =IF(P27=I27,(F27+D27)/2,0) -> 0 | S27: =IF(P27=J27,(D27+C27)/2,0) -> 0
A28: 14 | B28: ='القائمة الإسمية للمترشحين'!F28 -> 0 | C28: 0 | D28: 0 | E28: =IF(ABS(C28-D28)>=3,"يتطلب التصحيح الثالث"," ") | F28: 0 | G28: =IF(E28=" ",(C28+D28)/2," ") -> 0 | H28: =ABS(F28-C28) -> 0 | I28: =ABS(D28-F28) -> 0 | J28: =ABS(C28-D28) -> 0 | K28: 0 | L28: =MAX(Q28:S28) -> 0 | P28: =MIN(H28:J28) -> 0 | Q28: =IF(P28=H28,(F28+C28)/2,0) -> 0 | R28: =IF(P28=I28,(F28+D28)/2,0) -> 0 | S28: =IF(P28=J28,(D28+C28)/2,0) -> 0
A29: 15 | B29: ='القائمة الإسمية للمترشحين'!F29 -> 0 | C29: 0 | D29: 0 | E29: =IF(ABS(C29-D29)>=3,"يتطلب التصحيح الثالث"," ") | F29: 0 | G29: =IF(E29=" ",(C29+D29)/2," ") -> 0 | H29: =ABS(F29-C29) -> 0 | I29: =ABS(D29-F29) -> 0 | J29: =ABS(C29-D29) -> 0 | K29: 0 | L29: =MAX(Q29:S29) -> 0 | P29: =MIN(H29:J29) -> 0 | Q29: =IF(P29=H29,(F29+C29)/2,0) -> 0 | R29: =IF(P29=I29,(F29+D29)/2,0) -> 0 | S29: =IF(P29=J29,(D29+C29)/2,0) -> 0
... A62: 48 | B62: ='القائمة الإسمية للمترشحين'!F62 -> 0 | C62: 0 | D62: 0 | E62: =IF(ABS(C62-D62)>=3,"يتطلب التصحيح الثالث"," ") | F62: 0 | G62: =IF(E62=" ",(C62+D62)/2," ") -> 0 | H62: =ABS(F62-C62) -> 0 | I62: =ABS(D62-F62) -> 0 | J62: =ABS(C62-D62) -> 0 | K62: 0 | L62: =MAX(Q62:S62) -> 0 | P62: =MIN(H62:J62) -> 0 | Q62: =IF(P62=H62,(F62+C62)/2,0) -> 0 | R62: =IF(P62=I62,(F62+D62)/2,0) -> 0 | S62: =IF(P62=J62,(D62+C62)/2,0) -> 0
A63: 49 | B63: ='القائمة الإسمية للمترشحين'!F63 -> 0 | C63: 0 | D63: 0 | E63: =IF(ABS(C63-D63)>=3,"يتطلب التصحيح الثالث"," ") | F63: 0 | G63: =IF(E63=" ",(C63+D63)/2," ") -> 0 | H63: =ABS(F63-C63) -> 0 | I63: =ABS(D63-F63) -> 0 | J63: =ABS(C63-D63) -> 0 | K63: 0 | L63: =MAX(Q63:S63) -> 0 | M63: إمضاء لجنة التصحيح | P63: =MIN(H63:J63) -> 0 | Q63: =IF(P63=H63,(F63+C63)/2,0) -> 0 | R63: =IF(P63=I63,(F63+D63)/2,0) -> 0 | S63: =IF(P63=J63,(D63+C63)/2,0) -> 0
A64: 50 | B64: ='القائمة الإسمية للمترشحين'!F64 -> 0 | C64: 0 | D64: 0 | E64: =IF(ABS(C64-D64)>=3,"يتطلب التصحيح الثالث"," ") | F64: 0 | G64: =IF(E64=" ",(C64+D64)/2," ") -> 0 | H64: =ABS(F64-C64) -> 0 | I64: =ABS(D64-F64) -> 0 | J64: =ABS(C64-D64) -> 0 | K64: 0 | L64: =MAX(Q64:S64) -> 0 | P64: =MIN(H64:J64) -> 0 | Q64: =IF(P64=H64,(F64+C64)/2,0) -> 0 | R64: =IF(P64=I64,(F64+D64)/2,0) -> 0 | S64: =IF(P64=J64,(D64+C64)/2,0) -> 0
A65: 51 | B65: ='القائمة الإسمية للمترشحين'!F65 -> 0 | C65: 0 | D65: 0 | E65: =IF(ABS(C65-D65)>=3,"يتطلب التصحيح الثالث"," ") | F65: 0 | G65: =IF(E65=" ",(C65+D65)/2," ") -> 0 | H65: =ABS(F65-C65) -> 0 | I65: =ABS(D65-F65) -> 0 | J65: =ABS(C65-D65) -> 0 | K65: 0 | L65: =MAX(Q65:S65) -> 0 | P65: =MIN(H65:J65) -> 0 | Q65: =IF(P65=H65,(F65+C65)/2,0) -> 0 | R65: =IF(P65=I65,(F65+D65)/2,0) -> 0 | S65: =IF(P65=J65,(D65+C65)/2,0) -> 0
L68: إمضاء مسؤول أمانة المسابقة

Sheet المحضر النهائي+ ِCode
A1: الجمهورية الجزائرية الديموقراطية الشعبية
A2: وزارة التعليم العالي والبحث العلمي
A3: جامعة عمــــــــــار ثليـجي - الأغــــــــــــــــــــــــــــــــــــواط
A4: كلية : العلوم الاقتصادية و التجارية و علوم التسيير
A6: محضر مداولات لمسابقة التكوين في الطور الثالث دكتوراه
A7: المرجع: القرار رقم 547 المؤرخ في 02-06-2016 ( وزارة التعليم العالي و البحث العلمي)
A8: التخصص : إدارة المؤسسات
A10: النتائج النهائية للمسابقة مشفرة
E11: معامل المقياس الأول | F11: 1
E12: معامل المقياس الثاني | F12: 3
B14: الرمز السري للمترشح
C15: الامتحـــــــان الأول :إدارة الموارد البشرية | D15: الامتحـــــــان الثاني :الإدارة الإسترتيجية
A16: الرقم | B16: الرمز السري | C16: علامة الإمتحان 1 | D16: علامة امتحان الثاني 1 | E16: معدل المسابقة | F16: الترتيب | G16: قرار اللجنة
A17: 1 | B17: ='القائمة الإسمية للمترشحين'!F15 -> G201 | C17: ='حجز النقاط المقياس الأول'!L15 -> 0 | D17: ='حجز النقاط المقياس الثاني'!L15 -> 0 | E17: =(C17*$F$11+D17*$F$12)/($F$11+$F$12) -> 0 | F17: =RANK(E17,$E$17:$E$67,0) -> 1 | G17: ق/اللجنة | H17: إمضاء لجنة التصحيح
A18: 2 | B18: ='القائمة الإسمية للمترشحين'!F16 -> G202 | C18: ='حجز النقاط المقياس الأول'!L16 -> 0 | D18: ='حجز النقاط المقياس الثاني'!L16 -> 0 | E18: =(C18*$F$11+D18*$F$12)/($F$11+$F$12) -> 0 | F18: =RANK(E18,$E$17:$E$67,0) -> 1 | G18: ق/اللجنة
A19: 3 | B19: ='القائمة الإسمية للمترشحين'!F17 -> G203 | C19: ='حجز النقاط المقياس الأول'!L17 -> 0 | D19: ='حجز النقاط المقياس الثاني'!L17 -> 0 | E19: =(C19*$F$11+D19*$F$12)/($F$11+$F$12) -> 0 | F19: =RANK(E19,$E$17:$E$67,0) -> 1 | G19: ق/اللجنة | P19: ق/اللجنة
A20: 4 | B20: ='القائمة الإسمية للمترشحين'!F18 -> 0 | C20: ='حجز النقاط المقياس الأول'!L18 -> 0 | D20: ='حجز النقاط المقياس الثاني'!L18 -> 0 | E20: =(C20*$F$11+D20*$F$12)/($F$11+$F$12) -> 0 | F20: =RANK(E20,$E$17:$E$67,0) -> 1 | G20: ق/اللجنة | P20: ناحج(ة)
A21: 5 | B21: ='القائمة الإسمية للمترشحين'!F19 -> 0 | C21: ='حجز النقاط المقياس الأول'!L19 -> 0 | D21: ='حجز النقاط المقياس الثاني'!L19 -> 0 | E21: =(C21*$F$11+D21*$F$12)/($F$11+$F$12) -> 0 | F21: =RANK(E21,$E$17:$E$67,0) -> 1 | G21: ق/اللجنة | P21: منقطع(ة)
A22: 6 | B22: ='القائمة الإسمية للمترشحين'!F20 -> 0 | C22: ='حجز النقاط المقياس الأول'!L20 -> 0 | D22: ='حجز النقاط المقياس الثاني'!L20 -> 0 | E22: =(C22*$F$11+D22*$F$12)/($F$11+$F$12) -> 0 | F22: =RANK(E22,$E$17:$E$67,0) -> 1 | G22: ق/اللجنة | P22: غائب(ة)
A23: 7 | B23: ='القائمة الإسمية للمترشحين'!F21 -> 0 | C23: ='حجز النقاط المقياس الأول'!L21 -> 0 | D23: ='حجز النقاط المقياس الثاني'!L21 -> 0 | E23: =(C23*$F$11+D23*$F$12)/($F$11+$F$12) -> 0 | F23: =RANK(E23,$E$17:$E$67,0) -> 1 | G23: ق/اللجنة | P23: راسب(ة)
A24: 8 | B24: ='القائمة الإسمية للمترشحين'!F22 -> 0 | C24: ='حجز النقاط المقياس الأول'!L22 -> 0 | D24: ='حجز النقاط المقياس الثاني'!L22 -> 0 | E24: =(C24*$F$11+D24*$F$12)/($F$11+$F$12) -> 0 | F24: =RANK(E24,$E$17:$E$67,0) -> 1 | G24: ق/اللجنة
A25: 9 | B25: ='القائمة الإسمية للمترشحين'!F23 -> 0 | C25: ='حجز النقاط المقياس الأول'!L23 -> 0 | D25: ='حجز النقاط المقياس الثاني'!L23 -> 0 | E25: =(C25*$F$11+D25*$F$12)/($F$11+$F$12) -> 0 | F25: =RANK(E25,$E$17:$E$67,0) -> 1 | G25: ق/اللجنة
A26: 10 | B26: ='القائمة الإسمية للمترشحين'!F24 -> 0 | C26: ='حجز النقاط المقياس الأول'!L24 -> 0 | D26: ='حجز النقاط المقياس الثاني'!L24 -> 0 | E26: =(C26*$F$11+D26*$F$12)/($F$11+$F$12) -> 0 | F26: =RANK(E26,$E$17:$E$67,0) -> 1 | G26: ق/اللجنة
A27: 11 | B27: ='القائمة الإسمية للمترشحين'!F25 -> 0 | C27: ='حجز النقاط المقياس الأول'!L25 -> 0 | D27: ='حجز النقاط المقياس الثاني'!L25 -> 0 | E27: =(C27*$F$11+D27*$F$12)/($F$11+$F$12) -> 0 | F27: =RANK(E27,$E$17:$E$67,0) -> 1 | G27: ق/اللجنة
A28: 12 | B28: ='القائمة الإسمية للمترشحين'!F26 -> 0 | C28: ='حجز النقاط المقياس الأول'!L26 -> 0 | D28: ='حجز النقاط المقياس الثاني'!L26 -> 0 | E28: =(C28*$F$11+D28*$F$12)/($F$11+$F$12) -> 0 | F28: =RANK(E28,$E$17:$E$67,0) -> 1 | G28: ق/اللجنة
A29: 13 | B29: ='القائمة الإسمية للمترشحين'!F27 -> 0 | C29: ='حجز النقاط المقياس الأول'!L27 -> 0 | D29: ='حجز النقاط المقياس الثاني'!L27 -> 0 | E29: =(C29*$F$11+D29*$F$12)/($F$11+$F$12) -> 0 | F29: =RANK(E29,$E$17:$E$67,0) -> 1 | G29: ق/اللجنة
A30: 14 | B30: ='القائمة الإسمية للمترشحين'!F28 -> 0 | C30: ='حجز النقاط المقياس الأول'!L28 -> 0 | D30: ='حجز النقاط المقياس الثاني'!L28 -> 0 | E30: =(C30*$F$11+D30*$F$12)/($F$11+$F$12) -> 0 | F30: =RANK(E30,$E$17:$E$67,0) -> 1 | G30: ق/اللجنة
A31: 15 | B31: ='القائمة الإسمية للمترشحين'!F29 -> 0 | C31: ='حجز النقاط المقياس الأول'!L29 -> 0 | D31: ='حجز النقاط المقياس الثاني'!L29 -> 0 | E31: =(C31*$F$11+D31*$F$12)/($F$11+$F$12) -> 0 | F31: =RANK(E31,$E$17:$E$67,0) -> 1 | G31: ق/اللجنة
A32: 16 | B32: ='القائمة الإسمية للمترشحين'!F30 -> 0 | C32: ='حجز النقاط المقياس الأول'!L30 -> 0 | D32: ='حجز النقاط المقياس الثاني'!L30 -> 0 | E32: =(C32*$F$11+D32*$F$12)/($F$11+$F$12) -> 0 | F32: =RANK(E32,$E$17:$E$67,0) -> 1 | G32: ق/اللجنة
A33: 17 | B33: ='القائمة الإسمية للمترشحين'!F31 -> 0 | C33: ='حجز النقاط المقياس الأول'!L31 -> 0 | D33: ='حجز النقاط المقياس الثاني'!L31 -> 0 | E33: =(C33*$F$11+D33*$F$12)/($F$11+$F$12) -> 0 | F33: =RANK(E33,$E$17:$E$67,0) -> 1 | G33: ق/اللجنة
A34: 18 | B34: ='القائمة الإسمية للمترشحين'!F32 -> 0 | C34: ='حجز النقاط المقياس الأول'!L32 -> 0 | D34: ='حجز النقاط المقياس الثاني'!L32 -> 0 | E34: =(C34*$F$11+D34*$F$12)/($F$11+$F$12) -> 0 | F34: =RANK(E34,$E$17:$E$67,0) -> 1 | G34: ق/اللجنة
A35: 19 | B35: ='القائمة الإسمية للمترشحين'!F33 -> 0 | C35: ='حجز النقاط المقياس الأول'!L33 -> 0 | D35: ='حجز النقاط المقياس الثاني'!L33 -> 0 | E35: =(C35*$F$11+D35*$F$12)/($F$11+$F$12) -> 0 | F35: =RANK(E35,$E$17:$E$67,0) -> 1 | G35: ق/اللجنة
... A64: 48 | B64: ='القائمة الإسمية للمترشحين'!F62 -> 0 | C64: ='حجز النقاط المقياس الأول'!L62 -> 0 | D64: ='حجز النقاط المقياس الثاني'!L62 -> 0 | E64: =(C64*$F$11+D64*$F$12)/($F$11+$F$12) -> 0 | F64: =RANK(E64,$E$17:$E$67,0) -> 1 | G64: ق/اللجنة
A65: 49 | B65: ='القائمة الإسمية للمترشحين'!F63 -> 0 | C65: ='حجز النقاط المقياس الأول'!L63 -> 0 | D65: ='حجز النقاط المقياس الثاني'!L63 -> 0 | E65: =(C65*$F$11+D65*$F$12)/($F$11+$F$12) -> 0 | F65: =RANK(E65,$E$17:$E$67,0) -> 1 | G65: ق/اللجنة | H65: إمضاء لجنة التصحيح
A66: 50 | B66: ='القائمة الإسمية للمترشحين'!F64 -> 0 | C66: ='حجز النقاط المقياس الأول'!L64 -> 0 | D66: ='حجز النقاط المقياس الثاني'!L64 -> 0 | E66: =(C66*$F$11+D66*$F$12)/($F$11+$F$12) -> 0 | F66: =RANK(E66,$E$17:$E$67,0) -> 1 | G66: ق/اللجنة
A67: 51 | B67: ='القائمة الإسمية للمترشحين'!F65 -> 0 | C67: ='حجز النقاط المقياس الأول'!L65 -> 0 | D67: ='حجز النقاط المقياس الثاني'!L65 -> 0 | E67: =(C67*$F$11+D67*$F$12)/($F$11+$F$12) -> 0 | F67: =RANK(E67,$E$17:$E$67,0) -> 1 | G67: ق/اللجنة
A69: أعضاء لجنة التكوين | D69: رئيس اللجنة العلمية | E69: رئيس المجلس العلمي | H69: العميد

Sheet المحضر النهــائي للمسابقة 
A1: الجمهورية الجزائرية الديموقراطية الشعبية
A2: وزارة التعليم العالي والبحث العلمي
A3: جامعة عمــــــــــار ثليـجي - الأغــــــــــــــــــــــــــــــــــــواط
A4: كلية :
A6: محضر مداولات لمسابقة التكوين في الطور الثالث دكتوراه
A7: المرجع: القرار رقم 834 المؤرخ في 27-07-2017 ( وزارة التعليم العالي و البحث العلمي)
A8: التخصص :...................................
A10: النتائج النهائية
A12: الرقم | B12: الشفرة | C12: الاسم | D12: اللقب | E12: تاريخ الميلاد | F12: الجامعة الأصلية | G12: الاختبار الأول | H12: الاختبار الثاني | I12: المعدل العام للمسابقة | J12: الترتيب العام | K12: قرار اللجنة | M12: عدد المترشحين المعنين بالمسابقة: | T12: قرار اللجنة
A13: 1 | B13: ='المحضر النهائي+ ِCode'!B17 -> G201 | G13: ='المحضر النهائي+ ِCode'!C17 -> 0 | H13: ='المحضر النهائي+ ِCode'!D17 -> 0 | I13: =AVERAGE(G13:H13) -> 0 | J13: ='المحضر النهائي+ ِCode'!F17 -> 1 | T13: ناحج(ة)
A14: 2 | B14: ='المحضر النهائي+ ِCode'!B18 -> G202 | G14: ='المحضر النهائي+ ِCode'!C18 -> 0 | H14: ='المحضر النهائي+ ِCode'!D18 -> 0 | I14: =AVERAGE(G14:H14) -> 0 | J14: ='المحضر النهائي+ ِCode'!F18 -> 1 | T14: احتياط(ة)
A15: 3 | B15: ='المحضر النهائي+ ِCode'!B19 -> G203 | G15: ='المحضر النهائي+ ِCode'!C19 -> 0 | H15: ='المحضر النهائي+ ِCode'!D19 -> 0 | I15: =AVERAGE(G15:H15) -> 0 | J15: ='المحضر النهائي+ ِCode'!F19 -> 1 | M15: عدد المترشحين الغائبين: | T15: راسب(ة)
A16: 4 | B16: ='المحضر النهائي+ ِCode'!B20 -> 0 | G16: ='المحضر النهائي+ ِCode'!C20 -> 0 | H16: ='المحضر النهائي+ ِCode'!D20 -> 0 | I16: =AVERAGE(G16:H16) -> 0 | J16: ='المحضر النهائي+ ِCode'!F20 -> 1
A17: 5 | B17: ='المحضر النهائي+ ِCode'!B21 -> 0 | G17: ='المحضر النهائي+ ِCode'!C21 -> 0 | H17: ='المحضر النهائي+ ِCode'!D21 -> 0 | I17: =AVERAGE(G17:H17) -> 0 | J17: ='المحضر النهائي+ ِCode'!F21 -> 1
A18: 6 | B18: ='المحضر النهائي+ ِCode'!B22 -> 0 | G18: ='المحضر النهائي+ ِCode'!C22 -> 0 | H18: ='المحضر النهائي+ ِCode'!D22 -> 0 | I18: =AVERAGE(G18:H18) -> 0 | J18: ='المحضر النهائي+ ِCode'!F22 -> 1
A19: 7 | B19: ='المحضر النهائي+ ِCode'!B23 -> 0 | G19: ='المحضر النهائي+ ِCode'!C23 -> 0 | H19: ='المحضر النهائي+ ِCode'!D23 -> 0 | I19: =AVERAGE(G19:H19) -> 0 | J19: ='المحضر النهائي+ ِCode'!F23 -> 1 | M19: عدد المترشحين الحلضرين:
A20: 8 | B20: ='المحضر النهائي+ ِCode'!B24 -> 0 | G20: ='المحضر النهائي+ ِCode'!C24 -> 0 | H20: ='المحضر النهائي+ ِCode'!D24 -> 0 | I20: =AVERAGE(G20:H20) -> 0 | J20: ='المحضر النهائي+ ِCode'!F24 -> 1
A21: 9 | B21: ='المحضر النهائي+ ِCode'!B25 -> 0 | G21: ='المحضر النهائي+ ِCode'!C25 -> 0 | H21: ='المحضر النهائي+ ِCode'!D25 -> 0 | I21: =AVERAGE(G21:H21) -> 0 | J21: ='المحضر النهائي+ ِCode'!F25 -> 1
A22: 10 | B22: ='المحضر النهائي+ ِCode'!B26 -> 0 | G22: ='المحضر النهائي+ ِCode'!C26 -> 0 | H22: ='المحضر النهائي+ ِCode'!D26 -> 0 | I22: =AVERAGE(G22:H22) -> 0 | J22: ='المحضر النهائي+ ِCode'!F26 -> 1
A23: 11 | B23: ='المحضر النهائي+ ِCode'!B27 -> 0 | G23: ='المحضر النهائي+ ِCode'!C27 -> 0 | H23: ='المحضر النهائي+ ِCode'!D27 -> 0 | I23: =AVERAGE(G23:H23) -> 0 | J23: ='المحضر النهائي+ ِCode'!F27 -> 1
A24: 12 | B24: ='المحضر النهائي+ ِCode'!B28 -> 0 | G24: ='المحضر النهائي+ ِCode'!C28 -> 0 | H24: ='المحضر النهائي+ ِCode'!D28 -> 0 | I24: =AVERAGE(G24:H24) -> 0 | J24: ='المحضر النهائي+ ِCode'!F28 -> 1
A25: 13 | B25: ='المحضر النهائي+ ِCode'!B29 -> 0 | G25: ='المحضر النهائي+ ِCode'!C29 -> 0 | H25: ='المحضر النهائي+ ِCode'!D29 -> 0 | I25: =AVERAGE(G25:H25) -> 0 | J25: ='المحضر النهائي+ ِCode'!F29 -> 1
A26: 14 | B26: ='المحضر النهائي+ ِCode'!B30 -> 0 | G26: ='المحضر النهائي+ ِCode'!C30 -> 0 | H26: ='المحضر النهائي+ ِCode'!D30 -> 0 | I26: =AVERAGE(G26:H26) -> 0 | J26: ='المحضر النهائي+ ِCode'!F30 -> 1 | M26: إمضاء المصححين
A27: 15 | B27: ='المحضر النهائي+ ِCode'!B31 -> 0 | G27: ='المحضر النهائي+ ِCode'!C31 -> 0 | H27: ='المحضر النهائي+ ِCode'!D31 -> 0 | I27: =AVERAGE(G27:H27) -> 0 | J27: ='المحضر النهائي+ ِCode'!F31 -> 1
A28: 16 | B28: ='المحضر النهائي+ ِCode'!B32 -> 0 | G28: ='المحضر النهائي+ ِCode'!C32 -> 0 | H28: ='المحضر النهائي+ ِCode'!D32 -> 0 | I28: =AVERAGE(G28:H28) -> 0 | J28: ='المحضر النهائي+ ِCode'!F32 -> 1 | L28: 1.
A29: 17 | B29: ='المحضر النهائي+ ِCode'!B33 -> 0 | G29: ='المحضر النهائي+ ِCode'!C33 -> 0 | H29: ='المحضر النهائي+ ِCode'!D33 -> 0 | I29: =AVERAGE(G29:H29) -> 0 | J29: ='المحضر النهائي+ ِCode'!F33 -> 1
A30: 18 | B30: ='المحضر النهائي+ ِCode'!B34 -> 0 | G30: ='المحضر النهائي+ ِCode'!C34 -> 0 | H30: ='المحضر النهائي+ ِCode'!D34 -> 0 | I30: =AVERAGE(G30:H30) -> 0 | J30: ='المحضر النهائي+ ِCode'!F34 -> 1 | L30: 2.
A31: 19 | B31: ='المحضر النهائي+ ِCode'!B35 -> 0 | G31: ='المحضر النهائي+ ِCode'!C35 -> 0 | H31: ='المحضر النهائي+ ِCode'!D35 -> 0 | I31: =AVERAGE(G31:H31) -> 0 | J31: ='المحضر النهائي+ ِCode'!F35 -> 1
A32: 20 | B32: ='المحضر النهائي+ ِCode'!B36 -> 0 | G32: ='المحضر النهائي+ ِCode'!C36 -> 0 | H32: ='المحضر النهائي+ ِCode'!D36 -> 0 | I32: =AVERAGE(G32:H32) -> 0 | J32: ='المحضر النهائي+ ِCode'!F36 -> 1 | L32: 3.
A33: 21 | B33: ='المحضر النهائي+ ِCode'!B37 -> 0 | G33: ='المحضر النهائي+ ِCode'!C37 -> 0 | H33: ='المحضر النهائي+ ِCode'!D37 -> 0 | I33: =AVERAGE(G33:H33) -> 0 | J33: ='المحضر النهائي+ ِCode'!F37 -> 1
A34: 22 | B34: ='المحضر النهائي+ ِCode'!B38 -> 0 | G34: ='المحضر النهائي+ ِCode'!C38 -> 0 | H34: ='المحضر النهائي+ ِCode'!D38 -> 0 | I34: =AVERAGE(G34:H34) -> 0 | J34: ='المحضر النهائي+ ِCode'!F38 -> 1 | L34: 4.
A35: 23 | B35: ='المحضر النهائي+ ِCode'!B39 -> 0 | G35: ='المحضر النهائي+ ِCode'!C39 -> 0 | H35: ='المحضر النهائي+ ِCode'!D39 -> 0 | I35: =AVERAGE(G35:H35) -> 0 | J35: ='المحضر النهائي+ ِCode'!F39 -> 1
A36: 24 | B36: ='المحضر النهائي+ ِCode'!B40 -> 0 | G36: ='المحضر النهائي+ ِCode'!C40 -> 0 | H36: ='المحضر النهائي+ ِCode'!D40 -> 0 | I36: =AVERAGE(G36:H36) -> 0 | J36: ='المحضر النهائي+ ِCode'!F40 -> 1 | L36: 5.
A37: 25 | B37: ='المحضر النهائي+ ِCode'!B41 -> 0 | G37: ='المحضر النهائي+ ِCode'!C41 -> 0 | H37: ='المحضر النهائي+ ِCode'!D41 -> 0 | I37: =AVERAGE(G37:H37) -> 0 | J37: ='المحضر النهائي+ ِCode'!F41 -> 1
A38: 26 | B38: ='المحضر النهائي+ ِCode'!B42 -> 0 | G38: ='المحضر النهائي+ ِCode'!C42 -> 0 | H38: ='المحضر النهائي+ ِCode'!D42 -> 0 | I38: =AVERAGE(G38:H38) -> 0 | J38: ='المحضر النهائي+ ِCode'!F42 -> 1 | L38: 6.
A39: 27 | B39: ='المحضر النهائي+ ِCode'!B43 -> 0 | G39: ='المحضر النهائي+ ِCode'!C43 -> 0 | H39: ='المحضر النهائي+ ِCode'!D43 -> 0 | I39: =AVERAGE(G39:H39) -> 0 | J39: ='المحضر النهائي+ ِCode'!F43 -> 1
A40: 28 | B40: ='المحضر النهائي+ ِCode'!B44 -> 0 | G40: ='المحضر النهائي+ ِCode'!C44 -> 0 | H40: ='المحضر النهائي+ ِCode'!D44 -> 0 | I40: =AVERAGE(G40:H40) -> 0 | J40: ='المحضر النهائي+ ِCode'!F44 -> 1 | L40: 7.
A41: 29 | B41: ='المحضر النهائي+ ِCode'!B45 -> 0 | G41: ='المحضر النهائي+ ِCode'!C45 -> 0 | H41: ='المحضر النهائي+ ِCode'!D45 -> 0 | I41: =AVERAGE(G41:H41) -> 0 | J41: ='المحضر النهائي+ ِCode'!F45 -> 1
A42: 30 | B42: ='المحضر النهائي+ ِCode'!B46 -> 0 | G42: ='المحضر النهائي+ ِCode'!C46 -> 0 | H42: ='المحضر النهائي+ ِCode'!D46 -> 0 | I42: =AVERAGE(G42:H42) -> 0 | J42: ='المحضر النهائي+ ِCode'!F46 -> 1
A43: 31 | B43: ='المحضر النهائي+ ِCode'!B47 -> 0 | G43: ='المحضر النهائي+ ِCode'!C47 -> 0 | H43: ='المحضر النهائي+ ِCode'!D47 -> 0 | I43: =AVERAGE(G43:H43) -> 0 | J43: ='المحضر النهائي+ ِCode'!F47 -> 1
...

Sheet قتح الأقفال 
A1: الجمهورية الجزائرية الديموقراطية الشعبية
A2: وزارة التعليم العالي والبحث العلمي
A3: جامعة عمــــــــــار ثليـجي - الأغــــــــــــــــــــــــــــــــــــواط
A4: كلية :
A6: ملف فتح الأقفال و الترميز لمسابقة التكوين في الطور الثالث دكتوراه
A7: المرجع: القرار رقم 834 المؤرخ في 27-07-2017 ( وزارة التعليم العالي و البحث العلمي)
A8: التخصص :...................................
A10: النتائج النهائية
A12: الرقم | B12: الشفرة المعتمدة مركز الإمتحان | C12: الشفرة المعتمدة لجنة التشفير | D12: الاسم | E12: اللقب | F12: تاريخ الميلاد | G12: الجامعة الأصلية
A13: 1 | B13: ='القائمة الإسمية للمترشحين'!F15 -> G201
A14: 2 | B14: ='القائمة الإسمية للمترشحين'!F16 -> G202
A15: 3 | B15: ='القائمة الإسمية للمترشحين'!F17 -> G203
A16: 4 | B16: ='القائمة الإسمية للمترشحين'!F18 -> 0
A17: 5 | B17: ='القائمة الإسمية للمترشحين'!F19 -> 0
A18: 6 | B18: ='القائمة الإسمية للمترشحين'!F20 -> 0
A19: 7 | B19: ='القائمة الإسمية للمترشحين'!F21 -> 0
A20: 8 | B20: ='القائمة الإسمية للمترشحين'!F22 -> 0
A21: 9 | B21: ='القائمة الإسمية للمترشحين'!F23 -> 0
A22: 10 | B22: ='القائمة الإسمية للمترشحين'!F24 -> 0
A23: 11 | B23: ='القائمة الإسمية للمترشحين'!F25 -> 0
A24: 12 | B24: ='القائمة الإسمية للمترشحين'!F26 -> 0
... A63: 51 | B63: ='القائمة الإسمية للمترشحين'!F65 -> 0
A64: 52 | B64: ='القائمة الإسمية للمترشحين'!#REF! -> #REF!
A65: 53 | B65: ='القائمة الإسمية للمترشحين'!#REF! -> #REF!
A66: 54 | B66: ='القائمة الإسمية للمترشحين'!#REF! -> #REF!
A67: 55 | B67: ='القائمة الإسمية للمترشحين'!#REF! -> #REF!
A68: 56 | B68: ='القائمة الإسمية للمترشحين'!#REF! -> #REF!
A69: 57 | B69: ='القائمة الإسمية للمترشحين'!#REF! -> #REF!
A70: 58 | B70: ='القائمة الإسمية للمترشحين'!#REF! -> #REF!
A71: 59 | B71: ='القائمة الإسمية للمترشحين'!#REF! -> #REF!
A72: 60 | B72: ='القائمة الإسمية للمترشحين'!#REF! -> #REF!
A73: 61 | B73: ='القائمة الإسمية للمترشحين'!#REF! -> #REF!
A74: 62 | B74: ='القائمة الإسمية للمترشحين'!#REF! -> #REF!
A75: 63 | B75: ='القائمة الإسمية للمترشحين'!#REF! -> #REF!
... A112: 100 | B112: ='القائمة الإسمية للمترشحين'!#REF! -> #REF!
B117: إمضاء رئيس لجنة التكوين | F117: إمضاء رئيس الجنة العلمية
D127: المادة 15 : يرتب المترشحون ترتيبا نهائيا على أساس الجدارة بناء على المعدل العام المحصل عليه في اختبارات المسابقة الكتابية. يرتب المترشحون في حالة التساوي على أساس المعدل العام المحصل عليه في مسار التكوين في الطور الأول. المرجع: القرار رقم 547 المؤرخ في 02-06-2016 ( وزارة التعليم العالي و البحث العلمي)
